
##########################
        cloud_enum
   github.com/initstring
##########################


Keywords:    sskyroute
Mutations:   /home/skyroute/cloud-1/capstone/capstone/tools/cloud_enum/enum_tools/fuzz.txt
Brute-list:  /home/skyroute/cloud-1/capstone/capstone/tools/cloud_enum/enum_tools/fuzz.txt

[+] Mutations list imported: 3 items
[+] Mutated results: 19 items

++++++++++++++++++++++++++
      amazon checks
++++++++++++++++++++++++++

[+] Checking for S3 buckets
    [!] Timeout on userdatasskyroute.s3.ap-northeast-2.amazonaws.com. Investigate if there are many of these
  [1m[92mOPEN S3 BUCKET: http://sskyroute.s3.ap-northeast-2.amazonaws.com/[0m
Traceback (most recent call last):
  File "/home/skyroute/.local/lib/python3.8/site-packages/urllib3/connection.py", line 174, in _new_conn
    conn = connection.create_connection(
  File "/home/skyroute/.local/lib/python3.8/site-packages/urllib3/util/connection.py", line 72, in create_connection
    for res in socket.getaddrinfo(host, port, family, socket.SOCK_STREAM):
  File "/usr/lib/python3.8/socket.py", line 918, in getaddrinfo
    for res in _socket.getaddrinfo(host, port, family, type, proto, flags):
socket.gaierror: [Errno -3] Temporary failure in name resolution

During handling of the above exception, another exception occurred:

Traceback (most recent call last):
  File "/home/skyroute/.local/lib/python3.8/site-packages/urllib3/connectionpool.py", line 715, in urlopen
    httplib_response = self._make_request(
  File "/home/skyroute/.local/lib/python3.8/site-packages/urllib3/connectionpool.py", line 416, in _make_request
    conn.request(method, url, **httplib_request_kw)
  File "/home/skyroute/.local/lib/python3.8/site-packages/urllib3/connection.py", line 244, in request
    super(HTTPConnection, self).request(method, url, body=body, headers=headers)
  File "/usr/lib/python3.8/http/client.py", line 1256, in request
    self._send_request(method, url, body, headers, encode_chunked)
  File "/usr/lib/python3.8/http/client.py", line 1302, in _send_request
    self.endheaders(body, encode_chunked=encode_chunked)
  File "/usr/lib/python3.8/http/client.py", line 1251, in endheaders
    self._send_output(message_body, encode_chunked=encode_chunked)
  File "/usr/lib/python3.8/http/client.py", line 1011, in _send_output
    self.send(msg)
  File "/usr/lib/python3.8/http/client.py", line 951, in send
    self.connect()
  File "/home/skyroute/.local/lib/python3.8/site-packages/urllib3/connection.py", line 205, in connect
    conn = self._new_conn()
  File "/home/skyroute/.local/lib/python3.8/site-packages/urllib3/connection.py", line 186, in _new_conn
    raise NewConnectionError(
urllib3.exceptions.NewConnectionError: <urllib3.connection.HTTPConnection object at 0x7fbde721eee0>: Failed to establish a new connection: [Errno -3] Temporary failure in name resolution

During handling of the above exception, another exception occurred:

Traceback (most recent call last):
  File "/home/skyroute/.local/lib/python3.8/site-packages/requests/adapters.py", line 439, in send
    resp = conn.urlopen(
  File "/home/skyroute/.local/lib/python3.8/site-packages/urllib3/connectionpool.py", line 799, in urlopen
    retries = retries.increment(
  File "/home/skyroute/.local/lib/python3.8/site-packages/urllib3/util/retry.py", line 592, in increment
    raise MaxRetryError(_pool, url, error or ResponseError(cause))
urllib3.exceptions.MaxRetryError: HTTPConnectionPool(host='sskyroute.s3.ap-northeast-2.amazonaws.com', port=80): Max retries exceeded with url: / (Caused by NewConnectionError('<urllib3.connection.HTTPConnection object at 0x7fbde721eee0>: Failed to establish a new connection: [Errno -3] Temporary failure in name resolution'))

During handling of the above exception, another exception occurred:

Traceback (most recent call last):
  File "/home/skyroute/cloud-1/capstone/capstone/tools/cloud_enum/cloud_enum.py", line 277, in <module>
    main()
  File "/home/skyroute/cloud-1/capstone/capstone/tools/cloud_enum/cloud_enum.py", line 262, in main
    aws_checks.run_all(names, args)
  File "/home/skyroute/cloud-1/capstone/capstone/tools/cloud_enum/enum_tools/aws_checks.py", line 150, in run_all
    check_s3_buckets(names, args.threads)
  File "/home/skyroute/cloud-1/capstone/capstone/tools/cloud_enum/enum_tools/aws_checks.py", line 98, in check_s3_buckets
    utils.get_url_batch(candidates, use_ssl=False,
  File "/home/skyroute/cloud-1/capstone/capstone/tools/cloud_enum/enum_tools/utils.py", line 122, in get_url_batch
    check = callback(batch_results[url])
  File "/home/skyroute/cloud-1/capstone/capstone/tools/cloud_enum/enum_tools/aws_checks.py", line 61, in print_s3_response
    utils.list_bucket_contents(reply.url)
  File "/home/skyroute/cloud-1/capstone/capstone/tools/cloud_enum/enum_tools/utils.py", line 253, in list_bucket_contents
    reply = requests.get(bucket)
  File "/home/skyroute/.local/lib/python3.8/site-packages/requests/api.py", line 75, in get
    return request('get', url, params=params, **kwargs)
  File "/home/skyroute/.local/lib/python3.8/site-packages/requests/api.py", line 61, in request
    return session.request(method=method, url=url, **kwargs)
  File "/home/skyroute/.local/lib/python3.8/site-packages/requests/sessions.py", line 542, in request
    resp = self.send(prep, **send_kwargs)
  File "/home/skyroute/.local/lib/python3.8/site-packages/requests/sessions.py", line 655, in send
    r = adapter.send(request, **kwargs)
  File "/home/skyroute/.local/lib/python3.8/site-packages/requests/adapters.py", line 516, in send
    raise ConnectionError(e, request=request)
requests.exceptions.ConnectionError: HTTPConnectionPool(host='sskyroute.s3.ap-northeast-2.amazonaws.com', port=80): Max retries exceeded with url: / (Caused by NewConnectionError('<urllib3.connection.HTTPConnection object at 0x7fbde721eee0>: Failed to establish a new connection: [Errno -3] Temporary failure in name resolution'))
